<?xml version="1.0"?>
<robot 
	xmlns:xi="http://www.w3.org/2001/XInclude"
	xmlns:gazebo="http://playerstage.sourceforge.net/gazebo/xmlschema/#gz"
    xmlns:model="http://playerstage.sourceforge.net/gazebo/xmlschema/#model"
	xmlns:sensor="http://playerstage.sourceforge.net/gazebo/xmlschema/#sensor"
	xmlns:body="http://playerstage.sourceforge.net/gazebo/xmlschema/#body"
    xmlns:geom="http://playerstage.sourceforge.net/gazebo/xmlschema/#geom"
    xmlns:joint="http://playerstage.sourceforge.net/gazebo/xmlschema/#joint"
	xmlns:controller="http://playerstage.sourceforge.net/gazebo/xmlschema/#controller"
	xmlns:interface="http://playerstage.sourceforge.net/gazebo/xmlschema/#interface"
	xmlns:rendering="http://playerstage.sourceforge.net/gazebo/xmlschema/#rendering"
    xmlns:renderable="http://playerstage.sourceforge.net/gazebo/xmlschema/#renderable"
    xmlns:physics="http://playerstage.sourceforge.net/gazebo/xmlschema/#physics"
	xmlns:xacro="http://ros.org/wiki/xacro" name="jaco">

<xacro:macro name="aero_arm" params="parent *origin prefix">
   <joint name="arm_fixture" type="fixed">
      <insert_block name="origin" />
      <parent link="${parent}"/>
      <child link="${prefix}_base_link"/>
    </joint> 

  <link name="${prefix}_base_link">
    <inertial>
      <origin
        xyz="0 0 0"
        rpy="0 0 0" />
      <mass
        value="0.001" />
      <inertia
        ixx="0.001"
        ixy="0.001"
        ixz="0.001"
        iyy="0.001"
        iyz="0.001"
        izz="0.001" />
    </inertial>
    <visual>
      <origin
        xyz="0 0 0"
        rpy="0 0 0" />
      <geometry>
        <mesh
          filename="package://aero_arm/meshes/base_link.STL" />
      </geometry>
      <material
        name="">
        <color
          rgba="0.792156862745098 0.819607843137255 0.933333333333333 1" />
      </material>
    </visual>
    <collision>
      <origin
        xyz="0 0 0"
        rpy="0 0 0" />
      <geometry>
        <mesh
          filename="package://aero_arm/meshes/base_link.STL" />
      </geometry>
    </collision>
  </link>
  <link
    name="${prefix}_Link1">
    <inertial>
      <origin
        xyz="0 0 0"
        rpy="0 0 0" />
      <mass
        value="0.001" />
   <inertia
        ixx="0.001"
        ixy="0.001"
        ixz="0.001"
        iyy="0.001"
        iyz="0.001"
        izz="0.001" />
    </inertial>

    <visual>
      <origin
        xyz="0 0 0"
        rpy="1.57 0 0" />
      <geometry>
        <mesh
          filename="package://aero_arm/meshes/Link1.STL" />
      </geometry>
      <material
        name="">
        <color
          rgba="0.792156862745098 0.819607843137255 0.933333333333333 1" />
      </material>
    </visual>
    <collision>
      <origin
        xyz="0 0 0"
        rpy="1.57 0 0" />
      <geometry>
        <mesh
          filename="package://aero_arm/meshes/Link1.STL" />
      </geometry>
    </collision>
  </link>
  <joint
    name="${prefix}_Joint1"
    type="continuous">
    <origin
      xyz="0 0 0"
      rpy="0 0 0" />
    <parent
      link="${prefix}_base_link" />
    <child
      link="${prefix}_Link1" />
    <axis
      xyz="0 0 -1" />
  </joint>
  <link
    name="${prefix}_Link2">
    <inertial>
      <origin
        xyz="0 0 0"
        rpy="0 0 0" />
      <mass
        value="0.001" />
    <inertia
        ixx="0.001"
        ixy="0.001"
        ixz="0.001"
        iyy="0.001"
        iyz="0.001"
        izz="0.001" />
    </inertial>
    <visual>
      <origin
        xyz=".205 0 0"
        rpy="3.14 0 0" />
      <geometry>
        <mesh
          filename="package://aero_arm/meshes/Link2.STL" />
      </geometry>
      <material
        name="">
        <color
          rgba="0.792156862745098 0.819607843137255 0.933333333333333 1" />
      </material>
    </visual>
    <collision>
      <origin
        xyz=".205 0 0"
        rpy="3.14 0 0" />
      <geometry>
        <mesh
          filename="package://aero_arm/meshes/Link2.STL" />
      </geometry>
    </collision>
  </link>
  <joint
    name="${prefix}_Joint2"
    type="continuous">
   <!-- <origin
      xyz="0 0 0.11875"
      rpy="0.0025506 -1.5708 0" /> -->
    <origin
      xyz="0 0 0.12"
      rpy="0.0 -1.5708 0" />
    <parent
      link="${prefix}_Link1" />
    <child
      link="${prefix}_Link2" />
    <axis
      xyz="0 0 -1" />
  </joint>
  <link
    name="${prefix}_Link3">
    <inertial>
<!--
      <origin
        xyz="0.01 -.04125 0"
        rpy="0.01 0 0" />
-->
     <origin
        xyz="0.00 0 0"
        rpy="0.00 0 0" />
      <mass
        value="0.001" />
  <inertia
        ixx="0.001"
        ixy="0.001"
        ixz="0.001"
        iyy="0.001"
        iyz="0.001"
        izz="0.001" />
    </inertial>

    <visual>
      <origin
        xyz="0 0 0"
        rpy="0 0 0" />
      <geometry>
        <mesh
          filename="package://aero_arm/meshes/Link4_origin.STL" scale="0.001 0.001 0.001"/>
      </geometry>
      <material
        name="">
        <color
          rgba="0.792156862745098 0.819607843137255 0.933333333333333 1" />
      </material>
    </visual>
    <collision>
      <origin
        xyz="0 0 0"
        rpy="0 0 0" />
      <geometry>
        <mesh
          filename="package://aero_arm/meshes/Link4_origin.STL" scale="0.001 0.001 0.001"/>
      </geometry>
    </collision>
  </link>
  <joint
    name="${prefix}_Joint3"
    type="continuous">
<!--
    <origin
      xyz="0.40806 -0.038517 0"
      rpy="-3.1416 -7.9134E-09 -0.28747" />
-->
    <origin
      xyz="0.41 0 0"
      rpy="-3.1416 0 -0.28747" />
    <parent
      link="${prefix}_Link2" />
    <child
      link="${prefix}_Link3" />
    <axis
      xyz="0 0 -1" />
  </joint>
  <link
    name="${prefix}_Link4">
    <inertial>
      <origin
        xyz="0 0 0"
        rpy="0 0 0" />
      <mass
        value="0.001" />
 <inertia
        ixx="0.001"
        ixy="0.001"
        ixz="0.001"
        iyy="0.001"
        iyz="0.001"
        izz="0.001" />
    </inertial>
    <visual>
      <origin
        xyz="0 0 0"
        rpy="0 0 0" />
      <geometry>
        <mesh
          filename="package://aero_arm/meshes/origin_fixed.STL" scale="0.001 0.001 0.001"/>
      </geometry>
      <material
        name="">
        <color
          rgba="0.792156862745098 0.819607843137255 0.933333333333333 1" />
      </material>
    </visual>
    <collision>
      <origin
        xyz="0 0 0"
        rpy="0 0 0" />
      <geometry>
        <mesh
          filename="package://aero_arm/meshes/origin_fixed.STL" scale="0.001 0.001 0.001"/>
      </geometry>
    </collision>
  </link>
  <joint
    name="${prefix}_Joint4"
    type="continuous">
<!--
    <origin
      xyz="0.12269 0.16673 0.011497"
      rpy="1.5708 0.064781 -0.63437" />
-->
   <origin
      xyz="0.2073 0.0 0.011497"
      rpy="0 -1.5708 0.0"/>

    <parent
      link="${prefix}_Link3" />
    <child
      link="${prefix}_Link4" />
    <axis
      xyz="0 0 1" />
  </joint>
  <link
    name="${prefix}_Link5">
    <inertial>
      <origin
        xyz="0 0 0"
        rpy="0 0 0" />
      <mass
        value="0.001" />
 <inertia
        ixx="0.001"
        ixy="0.001"
        ixz="0.001"
        iyy="0.001"
        iyz="0.001"
        izz="0.001" />
    </inertial>
    <visual>
      <origin
        xyz="0 0 0"
        rpy="0 0 0" />
      <geometry>
        <mesh
          filename="package://aero_arm/meshes/origin_fixed.STL" scale="0.001 0.001 0.001"/>
      </geometry>
      <material
        name="">
        <color
          rgba="0.792156862745098 0.819607843137255 0.933333333333333 1" />
      </material>
    </visual>
    <collision>
      <origin
        xyz="0 0 0"
        rpy="0 0 0" />
      <geometry>
        <mesh
          filename="package://aero_arm/meshes/origin_fixed.STL" scale="0.001 0.001 0.001"/>
      </geometry>
    </collision>
  </link>
  <joint
    name="${prefix}_Joint5"
    type="continuous">
<!--
    <origin
      xyz="0.030052 -0.016526 -0.065632"
      rpy="0.12154 -0.95472 -0.65131" />
-->
    <origin
      xyz="0.027925 -0.019554 -0.065738"
      rpy="0.12154 -0.95472 -0.65131" />

    <parent
      link="${prefix}_Link4" />
    <child
      link="${prefix}_Link5" />
    <axis
      xyz="0 0 1" />
  </joint>
  <link
    name="${prefix}_Gripper">
    <inertial>
      <origin
        xyz="0 0 0"
        rpy="0 0 0" />
      <mass
        value="0.001" />
 <inertia
        ixx="0.001"
        ixy="0.001"
        ixz="0.001"
        iyy="0.001"
        iyz="0.001"
        izz="0.001" />
    </inertial>
    <visual>
      <origin
        xyz="0 0 0"
        rpy="0 0 0" />
      <geometry>
        <mesh
          filename="package://aero_arm/meshes/Gripper_origin.STL" scale="0.001 0.001 0.001"/>
      </geometry>
      <material
        name="">
        <color
          rgba="0.792156862745098 0.819607843137255 0.933333333333333 1" />
      </material>
    </visual>
    <collision>
      <origin
        xyz="0 0 0"
        rpy="0 0 0" />
      <geometry>
        <mesh
          filename="package://aero_arm/meshes/Gripper_origin.STL" scale="0.001 0.001 0.001" />
      </geometry>
    </collision>
  </link>
  <joint
    name="${prefix}_Joint6"
    type="continuous">
<!--
    <origin
      xyz="-0.024641 -0.023854 -0.065632"
      rpy="-2.4455 0.72653 1.6683" />
    
--> 
    <origin
      xyz="0.027925 -0.019554 -0.065738"
      rpy="0.48869  2.1800 0" />
    <parent
      link="${prefix}_Link5" />
    <child
      link="${prefix}_Gripper" />
    <axis
      xyz="0 0 1" />
  </joint>
</xacro:macro>
</robot>
