<?xml version="1.0" ?>
<!-- =================================================================================== -->
<!-- |    This document was autogenerated by xacro from j2_7s_3_standalone.xacro       | -->
<!-- |    EDITING THIS FILE BY HAND IS NOT RECOMMENDED                                 | -->
<!-- =================================================================================== -->
<!-- j2_7s_3 refers to jaco v2 7DOF spherical 3fingers -->
<root xmlns:body="http://playerstage.sourceforge.net/gazebo/xmlschema/#body" xmlns:controller="http://playerstage.sourceforge.net/gazebo/xmlschema/#controller" xmlns:gazebo="http://playerstage.sourceforge.net/gazebo/xmlschema/#gz" xmlns:geom="http://playerstage.sourceforge.net/gazebo/xmlschema/#geom" xmlns:interface="http://playerstage.sourceforge.net/gazebo/xmlschema/#interface" xmlns:joint="http://playerstage.sourceforge.net/gazebo/xmlschema/#joint" xmlns:model="http://playerstage.sourceforge.net/gazebo/xmlschema/#model" xmlns:physics="http://playerstage.sourceforge.net/gazebo/xmlschema/#physics" xmlns:renderable="http://playerstage.sourceforge.net/gazebo/xmlschema/#renderable" xmlns:rendering="http://playerstage.sourceforge.net/gazebo/xmlschema/#rendering" xmlns:sensor="http://playerstage.sourceforge.net/gazebo/xmlschema/#sensor" xmlns:xacro="http://ros.org/wiki/xacro" xmlns:xi="http://www.w3.org/2001/XInclude">
  <link name="root">
    <visual>
      <origin rpy="0 0 0" xyz="0 0 0"/>
      <geometry>
        <box size="0 0 0"/>
      </geometry>
      <!--<material name="Black" /> -->
    </visual>
    <collision>
      <origin rpy="0 0 0" xyz="0 0 0"/>
      <geometry>
        <box size="0 0 0"/>
      </geometry>
    </collision>
  </link>
  <link name="j2_7s_3_link_base">
    <visual>
      <geometry>
        <mesh filename="package://kinova_description/meshes/j2_7s_3_link_base.dae"/>
      </geometry>
      <material name="carbon_fiber">
        <color rgba="0.792156862745098 0.819607843137255 0.933333333333333 1"/>
      </material>
    </visual>
    <collision>
      <geometry>
        <mesh filename="package://kinova_description/meshes/j2_7s_3_link_base.dae"/>
      </geometry>
    </collision>
  </link>
  <joint name="j2_7s_3_joint_base" type="fixed">
    <parent link="root"/>
    <child link="j2_7s_3_link_base"/>
    <axis xyz="0 0 0"/>
    <limit effort="30" lower="0" upper="0" velocity="0.35"/>
    <origin rpy="0 0 0" xyz="0 0 0"/>
  </joint>
  <link name="j2_7s_3_link_1">
    <visual>
      <geometry>
        <mesh filename="package://kinova_description/meshes/j2_7s_3_link_1.dae"/>
      </geometry>
      <material name="carbon_fiber">
        <color rgba="0.792156862745098 0.819607843137255 0.933333333333333 1"/>
      </material>
    </visual>
    <collision>
      <geometry>
        <mesh filename="package://kinova_description/meshes/j2_7s_3_link_1.dae"/>
      </geometry>
    </collision>
  </link>
  <joint name="j2_7s_3_joint_1" type="continuous">
    <parent link="j2_7s_3_link_base"/>
    <child link="j2_7s_3_link_1"/>
    <axis xyz="0 0 1"/>
    <limit effort="30" lower="-6.28318530718" upper="6.28318530718" velocity="0.35"/>
    <origin rpy="0 0 0" xyz="0 0 0.15675"/>
  </joint>
  <link name="j2_7s_3_link_2">
    <visual>
      <geometry>
        <mesh filename="package://kinova_description/meshes/j2_7s_3_link_2.dae"/>
      </geometry>
      <material name="carbon_fiber">
        <color rgba="0.792156862745098 0.819607843137255 0.933333333333333 1"/>
      </material>
    </visual>
    <collision>
      <geometry>
        <mesh filename="package://kinova_description/meshes/j2_7s_3_link_2.dae"/>
      </geometry>
    </collision>
  </link>
  <joint name="j2_7s_3_joint_2" type="revolute">
    <parent link="j2_7s_3_link_1"/>
    <child link="j2_7s_3_link_2"/>
    <axis xyz="0 0 1"/>
    <limit effort="30" lower="-3.14159265359" upper="0.0" velocity="0.35"/>
    <origin rpy="-1.57079632679 0 3.14159265359" xyz="0 0.0016 -0.11875"/>
  </joint>
  <link name="j2_7s_3_link_3">
    <visual>
      <geometry>
        <mesh filename="package://kinova_description/meshes/j2_7s_3_link_3.dae"/>
      </geometry>
      <material name="carbon_fiber">
        <color rgba="0.792156862745098 0.819607843137255 0.933333333333333 1"/>
      </material>
    </visual>
    <collision>
      <geometry>
        <mesh filename="package://kinova_description/meshes/j2_7s_3_link_3.dae"/>
      </geometry>
    </collision>
  </link>
  <joint name="j2_7s_3_joint_3" type="continuous">
    <parent link="j2_7s_3_link_2"/>
    <child link="j2_7s_3_link_3"/>
    <axis xyz="0 0 1"/>
    <limit effort="30" lower="-3.92699081699" upper="0.785398163397" velocity="0.35"/>
    <origin rpy="3.14159265359 0 3.14159265359" xyz="0 -0.205 0"/>
  </joint>
  <link name="j2_7s_3_link_4">
    <visual>
      <geometry>
        <mesh filename="package://kinova_description/meshes/j2_7s_3_link_4.dae"/>
      </geometry>
      <material name="carbon_fiber">
        <color rgba="0.792156862745098 0.819607843137255 0.933333333333333 1"/>
      </material>
    </visual>
    <collision>
      <geometry>
        <mesh filename="package://kinova_description/meshes/j2_7s_3_link_4.dae"/>
      </geometry>
    </collision>
  </link>
  <joint name="j2_7s_3_joint_4" type="revolute">
    <parent link="j2_7s_3_link_3"/>
    <child link="j2_7s_3_link_4"/>
    <axis xyz="0 0 1"/>
    <limit effort="30" lower="-6.28318530718" upper="6.28318530718" velocity="0.35"/>
    <origin rpy="1.57079632679 1.57079632679 0" xyz="0 0 -0.205"/>
  </joint>
  <link name="j2_7s_3_link_5">
    <visual>
      <geometry>
        <mesh filename="package://kinova_description/meshes/j2_7s_3_link_5.dae"/>
      </geometry>
      <material name="carbon_fiber">
        <color rgba="0.792156862745098 0.819607843137255 0.933333333333333 1"/>
      </material>
    </visual>
    <collision>
      <geometry>
        <mesh filename="package://kinova_description/meshes/j2_7s_3_link_5.dae"/>
      </geometry>
    </collision>
  </link>
  <joint name="j2_7s_3_joint_5" type="continuous">
    <parent link="j2_7s_3_link_4"/>
    <child link="j2_7s_3_link_5"/>
    <axis xyz="0 0 1"/>
    <limit effort="30" lower="-6.28318530718" upper="6.28318530718" velocity="0.35"/>
    <origin rpy="-1.0471975512 0 0" xyz="0 0.2073 -0.0114"/>
  </joint>
  <link name="j2_7s_3_link_6">
    <visual>
      <geometry>
        <mesh filename="package://kinova_description/meshes/j2_7s_3_link_6.dae"/>
      </geometry>
      <material name="carbon_fiber">
        <color rgba="0.792156862745098 0.819607843137255 0.933333333333333 1"/>
      </material>
    </visual>
    <collision>
      <geometry>
        <mesh filename="package://kinova_description/meshes/j2_7s_3_link_6.dae"/>
      </geometry>
    </collision>
  </link>
  <joint name="j2_7s_3_joint_6" type="revolute">
    <parent link="j2_7s_3_link_5"/>
    <child link="j2_7s_3_link_6"/>
    <axis xyz="0 0 1"/>
    <limit effort="30" lower="-6.28318530718" upper="6.28318530718" velocity="0.35"/>
    <origin rpy="-1.0471975512 0 0" xyz="0 -0.03703 -0.06414"/>
  </joint>
  <link name="j2_7s_3_link_7">
    <visual>
      <geometry>
        <mesh filename="package://kinova_description/meshes/j2_7s_3_link_7.dae"/>
      </geometry>
      <material name="carbon_fiber">
        <color rgba="0.792156862745098 0.819607843137255 0.933333333333333 1"/>
      </material>
    </visual>
    <collision>
      <geometry>
        <mesh filename="package://kinova_description/meshes/j2_7s_3_link_7.dae"/>
      </geometry>
    </collision>
  </link>
  <joint name="j2_7s_3_joint_7" type="continuous">
    <parent link="j2_7s_3_link_6"/>
    <child link="j2_7s_3_link_7"/>
    <axis xyz="0 0 1"/>
    <limit effort="30" lower="-6.28318530718" upper="6.28318530718" velocity="0.35"/>
    <origin rpy="-1.0471975512 0 0" xyz="0 -0.03703 -0.06414"/>
  </joint>
  <link name="j2_7s_3_end_effector">
    <visual>
      <geometry>
        <mesh filename="package://kinova_description/meshes/j2_7s_3_end_effector.dae"/>
      </geometry>
      <material name="carbon_fiber">
        <color rgba="0.792156862745098 0.819607843137255 0.933333333333333 1"/>
      </material>
    </visual>
    <collision>
      <geometry>
        <mesh filename="package://kinova_description/meshes/j2_7s_3_end_effector.dae"/>
      </geometry>
    </collision>
  </link>
  <joint name="j2_7s_3_end_effector_offset" type="fixed">
    <parent link="j2_7s_3_link_7"/>
    <child link="j2_7s_3_end_effector"/>
    <axis xyz="0 0 0"/>
    <limit effort="30" lower="0" upper="0" velocity="0.35"/>
    <origin rpy="0 0 0" xyz="0 0 -0.1600"/>
  </joint>
</root>

