<?xml version="1.0"?>
<!-- for 3finger_hand and 2finger_hand -->


<root xmlns:xi="http://www.w3.org/2001/XInclude"
    xmlns:gazebo="http://playerstage.sourceforge.net/gazebo/xmlschema/#gz"
    xmlns:model="http://playerstage.sourceforge.net/gazebo/xmlschema/#model"
    xmlns:sensor="http://playerstage.sourceforge.net/gazebo/xmlschema/#sensor"
    xmlns:body="http://playerstage.sourceforge.net/gazebo/xmlschema/#body"
    xmlns:geom="http://playerstage.sourceforge.net/gazebo/xmlschema/#geom"
    xmlns:joint="http://playerstage.sourceforge.net/gazebo/xmlschema/#joint"
    xmlns:controller="http://playerstage.sourceforge.net/gazebo/xmlschema/#controller"
    xmlns:interface="http://playerstage.sourceforge.net/gazebo/xmlschema/#interface"
    xmlns:rendering="http://playerstage.sourceforge.net/gazebo/xmlschema/#rendering"
    xmlns:renderable="http://playerstage.sourceforge.net/gazebo/xmlschema/#renderable"
    xmlns:physics="http://playerstage.sourceforge.net/gazebo/xmlschema/#physics"
    xmlns:xacro="http://ros.org/wiki/xacro">

    <xacro:include filename="$(find kinova_description)/urdf/kinova_common.xacro" />

   
    <xacro:macro name="kinova_3fingers" params="link_hand prefix">

        <!-- finger1 Rot := Ry((1/2)*Pi) . Rx(12.1*((1/180)*Pi)+Pi) . Rz(-52.8*((1/180)*Pi)) -->
        <xacro:kinova_finger prefix="${prefix}" finger_number="1" hand="${link_hand}" finger_origin_xyz="0.00279 0.03126 -0.11467" finger_origin_rpy="-1.570796327 .649262481663582 1.35961148639407"/>
        <!-- finger2 Rot := Ry((1/2)*Pi) . Rx(10.58*((1/180)*Pi)) . Rz(-52.8*((1/180)*Pi)) -->
        <xacro:kinova_finger prefix="${prefix}" finger_number="2" hand="${link_hand}" finger_origin_xyz="0.02226 -0.02707 -0.11482" finger_origin_rpy="-1.570796327 .649262481663582 -1.38614049188413"/>
        <!-- finger3 Rot := Ry((1/2)*Pi) . Rx(-10.58*((1/180)*Pi)) . Rz(-52.8*((1/180)*Pi)) -->
        <xacro:kinova_finger prefix="${prefix}" finger_number="3" hand="${link_hand}" finger_origin_xyz="-0.02226 -0.02707 -0.11482" finger_origin_rpy="-1.570796327 .649262481663582 -1.75545216211587"/>
        
    </xacro:macro>


    <xacro:macro name="kinova_2fingers" params="link_hand prefix">

                <!-- FINGER 1 -->
                <!--<xacro:macro name="kinova_finger" params="prefix finger_number hand finger_origin_xyz finger_origin_rpy">-->

                    <!-- finger1 Rot := Ry((1/2)*Pi) . Rx(Pi) . Rz(-52.8*((1/180)*Pi)) -->
                    <!--<xacro:kinova_finger prefix="${prefix}" finger_number="1" hand="${link_hand}" finger_origin_xyz="-0.0025 0.03095 -0.11482" finger_origin_rpy="-1.570796327 .649262481663582 1.57079632679490"/>-->

                    <xacro:kinova_armlink link_name="${prefix}link_finger_1" link_mesh="finger_proximal" mesh_no="57"/>

                    <joint name="${prefix}joint_finger_1" type="revolute">
                        <parent link="${link_hand}"/>
                        <child link="${prefix}link_finger_1"/>
                        <axis xyz="0 0 1"/>
                        <origin xyz="-0.0025 0.03095 -0.11482" rpy="-1.570796327 .649262481663582 1.57079632679490"/>
                        <limit lower="0" upper="2" effort="2000" velocity="1"/>
                    </joint>
                        <transmission name="${prefix}joint_finger_1_trans">
                                <type>transmission_interface/SimpleTransmission</type>
                                <joint name="${prefix}joint_finger_1">
                                  <hardwareInterface>EffortJointInterface</hardwareInterface>
                                </joint>
                                <actuator name="${prefix}joint_finger_1_actuator">
                                <hardwareInterface>EffortJointInterface</hardwareInterface>
                                <mechanicalReduction>1</mechanicalReduction>
                                </actuator>
                        </transmission>



                    <xacro:kinova_armlink link_name="${prefix}link_finger_tip_1" link_mesh="finger_distal" mesh_no="58"/>

                    <joint name="${prefix}joint_finger_tip_1" type="fixed">
                        <parent link="${prefix}link_finger_1"/>
                        <child link="${prefix}link_finger_tip_1"/>
                        <axis xyz="0 0 1"/>
                        <origin xyz="0.044 -0.003 0" rpy="0 0 0"/>
                        <limit lower="0" upper="2" effort="2000" velocity="1"/>
                    </joint>

                <!--</xacro:macro>-->

                <!-- FINGER 2 -->
               <!--<xacro:macro name="kinova_finger" params="prefix finger_number hand finger_origin_xyz finger_origin_rpy">-->

                    <!-- finger2 Rot := Ry((1/2)*Pi) . Rz(-52.8*((1/180)*Pi))  -->
                    <!--<xacro:kinova_finger prefix="${prefix}" finger_number="2" hand="${link_hand}" finger_origin_xyz="-0.0025 -0.03095 -0.11482" finger_origin_rpy="-1.570796327 .649262481663582 -1.57079632679490"/>-->

                    <xacro:kinova_armlink link_name="${prefix}link_finger_2" link_mesh="finger_proximal" mesh_no="57"/>

                    <joint name="${prefix}joint_finger_2" type="revolute">
                        <parent link="${link_hand}"/>
                        <child link="${prefix}link_finger_2"/>
                        <axis xyz="0 0 1"/>
                        <mimic joint="${prefix}joint_finger_1" multiplier="1"/>
                        <origin xyz="-0.0025 -0.03095 -0.11482" rpy="-1.570796327 .649262481663582 -1.57079632679490"/>
                        <limit lower="0" upper="2" effort="2000" velocity="1"/>
                    </joint>
                        <transmission name="${prefix}joint_finger_2_trans">
                                <type>transmission_interface/SimpleTransmission</type>
                                <joint name="${prefix}joint_finger_2">
                                  <hardwareInterface>EffortJointInterface</hardwareInterface>
                                </joint>
                                <actuator name="${prefix}joint_finger_2_actuator">
                                <hardwareInterface>EffortJointInterface</hardwareInterface>
                                <mechanicalReduction>1</mechanicalReduction>
                                </actuator>
                        </transmission>



                    <xacro:kinova_armlink link_name="${prefix}link_finger_tip_2" link_mesh="finger_distal" mesh_no="58"/>

                    <joint name="${prefix}joint_finger_tip_2" type="fixed">
                        <parent link="${prefix}link_finger_2"/>
                        <child link="${prefix}link_finger_tip_2"/>
                        <axis xyz="0 0 1"/>
                        <origin xyz="0.044 -0.003 0" rpy="0 0 0"/>
                        <limit lower="0" upper="2" effort="2000" velocity="1"/>
                    </joint>

                <!--</xacro:macro>-->
        
    </xacro:macro>



</root>
