<?xml version="1.0"?>


<root xmlns:xi="http://www.w3.org/2001/XInclude"
	xmlns:gazebo="http://playerstage.sourceforge.net/gazebo/xmlschema/#gz"
    xmlns:model="http://playerstage.sourceforge.net/gazebo/xmlschema/#model"
	xmlns:sensor="http://playerstage.sourceforge.net/gazebo/xmlschema/#sensor"
	xmlns:body="http://playerstage.sourceforge.net/gazebo/xmlschema/#body"
    xmlns:geom="http://playerstage.sourceforge.net/gazebo/xmlschema/#geom"
    xmlns:joint="http://playerstage.sourceforge.net/gazebo/xmlschema/#joint"
	xmlns:controller="http://playerstage.sourceforge.net/gazebo/xmlschema/#controller"
	xmlns:interface="http://playerstage.sourceforge.net/gazebo/xmlschema/#interface"
	xmlns:rendering="http://playerstage.sourceforge.net/gazebo/xmlschema/#rendering"
    xmlns:renderable="http://playerstage.sourceforge.net/gazebo/xmlschema/#renderable"
    xmlns:physics="http://playerstage.sourceforge.net/gazebo/xmlschema/#physics"
	xmlns:xacro="http://ros.org/wiki/xacro">


    <property name="J_PI" value="3.1415926535897931" />

    <xacro:macro name="kinova_armlink" params="link_name link_mesh">
        <link name="${link_name}">
            <visual>
                <geometry>
                    <mesh
                        filename="package://kinova_description/meshes/${link_mesh}.dae"/>
                </geometry>
                <material name="carbon_fiber">
                    <color rgba="0.792156862745098 0.819607843137255 0.933333333333333 1" />
                </material>
            </visual>
            <collision>
                <geometry>
                    <mesh
                        filename="package://kinova_description/meshes/${link_mesh}.dae"/>
                </geometry>
            </collision>
        </link>
    </xacro:macro>

    <xacro:macro name="kinova_armjoint" params="joint_name type parent child joint_axis_xyz joint_origin_xyz joint_origin_rpy joint_lower_limit joint_upper_limit">
    <joint name="${joint_name}" type="${type}">
        <parent link="${parent}"/>
        <child link="${child}"/>
        <axis xyz="${joint_axis_xyz}"/>
        <limit effort="30" velocity="0.35" lower="${joint_lower_limit}" upper="${joint_upper_limit}"/>
        <origin xyz="${joint_origin_xyz}" rpy="${joint_origin_rpy}"/>
     </joint>
    </xacro:macro>


    <xacro:macro name="kinova_virtual_link" params="link_name">
        <link name="${link_name}">
            <visual>
                <geometry>
                    <box size = "0 0 0"/>
                </geometry>
            </visual>
            <collision>
                <geometry>
                    <box size = "0 0 0"/>
                </geometry>
            </collision>
        </link>
    </xacro:macro>

    <xacro:macro name="kinova_virtual_joint" params="joint_name type parent child joint_axis_xyz joint_origin_xyz joint_origin_rpy joint_lower_limit joint_upper_limit">
    <joint name="${joint_name}" type="${type}">
        <parent link="${parent}"/>
        <child link="${child}"/>
        <axis xyz="${joint_axis_xyz}"/>
        <limit effort="30" velocity="0.35" lower="${joint_lower_limit}" upper="${joint_upper_limit}"/>
        <origin xyz="${joint_origin_xyz}" rpy="${joint_origin_rpy}"/>
     </joint>
    </xacro:macro>


    <xacro:macro name="kinova_finger" params="prefix finger_number hand finger_origin_xyz finger_origin_rpy">

        <xacro:kinova_armlink link_name="${prefix}_link_finger_${finger_number}" link_mesh="finger_proximal"/>
        <joint name="${prefix}_joint_finger_${finger_number}" type="revolute">
            <parent link="${hand}"/>
            <child link="${prefix}_link_finger_${finger_number}"/>
            <axis xyz="0 0 1"/>
            <origin xyz="${finger_origin_xyz}" rpy="${finger_origin_rpy}"/>
            <limit lower="0" upper="2" effort="30" velocity="5"/>
        </joint>

        <xacro:kinova_armlink link_name="${prefix}_link_finger_tip_${finger_number}" link_mesh="finger_distal"/>
        <joint name="${prefix}_joint_finger_tip_${finger_number}" type="fixed">
            <parent link="${prefix}_link_finger_${finger_number}"/>
            <child link="${prefix}_link_finger_tip_${finger_number}"/>
            <axis xyz="0 0 1"/>
            <origin xyz="0.044 -0.003 0" rpy="0 0 0"/>
            <limit lower="0" upper="2" effort="30" velocity="5"/>
            <mimic joint="${J_PI/180*40}" multiplier="1.0" offset="0.0"/>
        </joint>

    </xacro:macro>

   
</root>
