<?xml version="1.0" ?>
<!-- =================================================================================== -->
<!-- |    This document was autogenerated by xacro from standalone_jaco2.xacro         | -->
<!-- |    EDITING THIS FILE BY HAND IS NOT RECOMMENDED                                 | -->
<!-- =================================================================================== -->
<robot name="jaco" xmlns:body="http://playerstage.sourceforge.net/gazebo/xmlschema/#body" xmlns:controller="http://playerstage.sourceforge.net/gazebo/xmlschema/#controller" xmlns:gazebo="http://playerstage.sourceforge.net/gazebo/xmlschema/#gz" xmlns:geom="http://playerstage.sourceforge.net/gazebo/xmlschema/#geom" xmlns:interface="http://playerstage.sourceforge.net/gazebo/xmlschema/#interface" xmlns:joint="http://playerstage.sourceforge.net/gazebo/xmlschema/#joint" xmlns:model="http://playerstage.sourceforge.net/gazebo/xmlschema/#model" xmlns:physics="http://playerstage.sourceforge.net/gazebo/xmlschema/#physics" xmlns:renderable="http://playerstage.sourceforge.net/gazebo/xmlschema/#renderable" xmlns:rendering="http://playerstage.sourceforge.net/gazebo/xmlschema/#rendering" xmlns:sensor="http://playerstage.sourceforge.net/gazebo/xmlschema/#sensor" xmlns:xacro="http://ros.org/wiki/xacro" xmlns:xi="http://www.w3.org/2001/XInclude">
  <link name="root">
    <visual>
      <origin rpy="0 0 0" xyz="0 0 0"/>
      <geometry>
        <box size="0 0 0"/>
        <!--making it slightly bigger in x and z direction-->
      </geometry>
      <!--<material name="Black" /> -->
    </visual>
    <collision>
      <origin rpy="0 0 0" xyz="0 0 0"/>
      <geometry>
        <box size="0 0 0"/>
        <!--making it slightly bigger in x and z direction-->
      </geometry>
    </collision>
  </link>
  <link name="jaco2_link_base">
    <visual>
      <geometry>
        <mesh filename="package://kinova_description/meshes/jaco2_link_base.dae"/>
      </geometry>
      <material name="carbon_fiber">
        <color rgba="0.792156862745098 0.819607843137255 0.933333333333333 1"/>
      </material>
    </visual>
    <collision>
      <geometry>
        <mesh filename="package://kinova_description/meshes/jaco2_link_base.dae"/>
      </geometry>
    </collision>
  </link>
  <joint name="jaco2_joint_base" type="fixed">
    <parent link="root"/>
    <child link="jaco2_link_base"/>
    <axis xyz="0 0 0"/>
    <limit effort="30" lower="0" upper="0" velocity="0.35"/>
    <origin rpy="0 0 0" xyz="0 0 0"/>
  </joint>
  <link name="jaco2_link_1">
    <visual>
      <geometry>
        <mesh filename="package://kinova_description/meshes/jaco2_link_1.dae"/>
      </geometry>
      <material name="carbon_fiber">
        <color rgba="0.792156862745098 0.819607843137255 0.933333333333333 1"/>
      </material>
    </visual>
    <collision>
      <geometry>
        <mesh filename="package://kinova_description/meshes/jaco2_link_1.dae"/>
      </geometry>
    </collision>
  </link>
  <joint name="jaco2_joint_1" type="continuous">
    <parent link="jaco2_link_base"/>
    <child link="jaco2_link_1"/>
    <axis xyz="0 0 -1"/>
    <limit effort="30" lower="-6.28318530718" upper="6.28318530718" velocity="0.35"/>
    <origin rpy="0 0 0" xyz="0 0 0.1535"/>
  </joint>
  <link name="jaco2_link_2">
    <visual>
      <geometry>
        <mesh filename="package://kinova_description/meshes/jaco2_link_2.dae"/>
      </geometry>
      <material name="carbon_fiber">
        <color rgba="0.792156862745098 0.819607843137255 0.933333333333333 1"/>
      </material>
    </visual>
    <collision>
      <geometry>
        <mesh filename="package://kinova_description/meshes/jaco2_link_2.dae"/>
      </geometry>
    </collision>
  </link>
  <joint name="jaco2_joint_2" type="revolute">
    <parent link="jaco2_link_1"/>
    <child link="jaco2_link_2"/>
    <axis xyz="0 0 1"/>
    <limit effort="30" lower="-3.14159265359" upper="0.0" velocity="0.35"/>
    <origin rpy="1.57079632679 0 0" xyz="0 0 0.1185"/>
  </joint>
  <link name="jaco2_link_3">
    <visual>
      <geometry>
        <mesh filename="package://kinova_description/meshes/jaco2_link_3.dae"/>
      </geometry>
      <material name="carbon_fiber">
        <color rgba="0.792156862745098 0.819607843137255 0.933333333333333 1"/>
      </material>
    </visual>
    <collision>
      <geometry>
        <mesh filename="package://kinova_description/meshes/jaco2_link_3.dae"/>
      </geometry>
    </collision>
  </link>
  <joint name="jaco2_joint_3" type="revolute">
    <parent link="jaco2_link_2"/>
    <child link="jaco2_link_3"/>
    <axis xyz="0 0 -1"/>
    <limit effort="30" lower="-3.92699081699" upper="0.785398163397" velocity="0.35"/>
    <origin rpy="3.14159265359 0 1.57079632679" xyz="0.41 0 0"/>
  </joint>
  <link name="jaco2_link_4">
    <visual>
      <geometry>
        <mesh filename="package://kinova_description/meshes/jaco2_link_4.dae"/>
      </geometry>
      <material name="carbon_fiber">
        <color rgba="0.792156862745098 0.819607843137255 0.933333333333333 1"/>
      </material>
    </visual>
    <collision>
      <geometry>
        <mesh filename="package://kinova_description/meshes/jaco2_link_4.dae"/>
      </geometry>
    </collision>
  </link>
  <joint name="jaco2_joint_4" type="continuous">
    <parent link="jaco2_link_3"/>
    <child link="jaco2_link_4"/>
    <axis xyz="0 0 -1"/>
    <limit effort="30" lower="-6.28318530718" upper="6.28318530718" velocity="0.35"/>
    <origin rpy="3.14159265359 1.57079632679 0" xyz="0.207 0 -0.01125"/>
  </joint>
  <link name="jaco2_link_5">
    <visual>
      <geometry>
        <mesh filename="package://kinova_description/meshes/jaco2_link_5.dae"/>
      </geometry>
      <material name="carbon_fiber">
        <color rgba="0.792156862745098 0.819607843137255 0.933333333333333 1"/>
      </material>
    </visual>
    <collision>
      <geometry>
        <mesh filename="package://kinova_description/meshes/jaco2_link_5.dae"/>
      </geometry>
    </collision>
  </link>
  <joint name="jaco2_joint_5" type="continuous">
    <parent link="jaco2_link_4"/>
    <child link="jaco2_link_5"/>
    <axis xyz="0 0 -1"/>
    <limit effort="30" lower="-6.28318530718" upper="6.28318530718" velocity="0.35"/>
    <origin rpy="0 -1.0471975512 0" xyz="0.03700 0 -0.06408"/>
  </joint>
  <link name="jaco2_link_hand">
    <visual>
      <geometry>
        <mesh filename="package://kinova_description/meshes/jaco2_link_hand.dae"/>
      </geometry>
      <material name="carbon_fiber">
        <color rgba="0.792156862745098 0.819607843137255 0.933333333333333 1"/>
      </material>
    </visual>
    <collision>
      <geometry>
        <mesh filename="package://kinova_description/meshes/jaco2_link_hand.dae"/>
      </geometry>
    </collision>
  </link>
  <joint name="jaco2_joint_6" type="continuous">
    <parent link="jaco2_link_5"/>
    <child link="jaco2_link_hand"/>
    <axis xyz="0 0 -1"/>
    <limit effort="30" lower="-6.28318530718" upper="6.28318530718" velocity="0.35"/>
    <origin rpy="-1.0471975512 0 1.57079632679" xyz="0.03700 0 -0.06408"/>
  </joint>
  <joint name="jaco2_link_base_to_api_origin" type="fixed">
    <parent link="jaco2_link_base"/>
    <child link="jaco2_api_origin"/>
    <origin rpy="0 0 0" xyz="0 0 0.028"/>
  </joint>
  <link name="jaco2_api_origin">
    <!--
         <visual>
           <geometry>
             <box xyz="0 0 0" size="0.1 0.1 0.1"/>
           </geometry>
         </visual>
         <collision>
           <geometry>
             <box xyz="0 0 0" size="0.1 0.1 0.1"/>
           </geometry>
         </collision>
         -->
  </link>
  <joint name="jaco2_link_hand_to_end_effector" type="fixed">
    <parent link="jaco2_link_hand"/>
    <child link="jaco2_end_effector"/>
    <origin rpy="0 3.14159265359 0" xyz="0 0 -0.1687"/>
  </joint>
  <link name="jaco2_end_effector"/>
  <link name="jaco2_link_finger_1">
    <visual>
      <geometry>
        <mesh filename="package://kinova_description/meshes/jaco2_link_finger_1.dae"/>
      </geometry>
      <material name="carbon_fiber">
        <color rgba="0.792156862745098 0.819607843137255 0.933333333333333 1"/>
      </material>
    </visual>
    <collision>
      <geometry>
        <mesh filename="package://kinova_description/meshes/jaco2_link_finger_1.dae"/>
      </geometry>
    </collision>
  </link>
  <joint name="jaco2_joint_finger_1" type="revolute">
    <parent link="jaco2_link_hand"/>
    <child link="jaco2_link_finger_1"/>
    <axis xyz="0 0 1"/>
    <origin rpy="-1.7983 1.117 3.1416" xyz="-0.03978 0 -0.10071"/>
    <limit effort="30" lower="0" upper="0.698131700798" velocity="5"/>
  </joint>
  <link name="jaco2_link_finger_tip_1">
    <visual>
      <geometry>
        <mesh filename="package://kinova_description/meshes/jaco2_link_finger_tip_1.dae"/>
      </geometry>
      <material name="carbon_fiber">
        <color rgba="0.792156862745098 0.819607843137255 0.933333333333333 1"/>
      </material>
    </visual>
    <collision>
      <geometry>
        <mesh filename="package://kinova_description/meshes/jaco2_link_finger_tip_1.dae"/>
      </geometry>
    </collision>
  </link>
  <joint name="jaco2_joint_finger_tip_1" type="revolute">
    <parent link="jaco2_link_finger_1"/>
    <child link="jaco2_link_finger_tip_1"/>
    <axis xyz="0 0 1"/>
    <origin rpy="0 0 0" xyz="0.035 -0.02595 -0.0025"/>
    <limit effort="30" lower="0" upper="0.698131700798" velocity="5"/>
    <mimic joint="jaco2_joint_finger_1" multiplier="0.0" offset="0.0"/>
  </joint>
  <link name="jaco2_link_finger_2">
    <visual>
      <geometry>
        <mesh filename="package://kinova_description/meshes/jaco2_link_finger_2.dae"/>
      </geometry>
      <material name="carbon_fiber">
        <color rgba="0.792156862745098 0.819607843137255 0.933333333333333 1"/>
      </material>
    </visual>
    <collision>
      <geometry>
        <mesh filename="package://kinova_description/meshes/jaco2_link_finger_2.dae"/>
      </geometry>
    </collision>
  </link>
  <joint name="jaco2_joint_finger_2" type="revolute">
    <parent link="jaco2_link_hand"/>
    <child link="jaco2_link_finger_2"/>
    <axis xyz="0 0 1"/>
    <origin rpy="-1.6222 1.117 -0.23615" xyz="0.03569 -0.0216 -0.10071"/>
    <limit effort="30" lower="0" upper="0.698131700798" velocity="5"/>
  </joint>
  <link name="jaco2_link_finger_tip_2">
    <visual>
      <geometry>
        <mesh filename="package://kinova_description/meshes/jaco2_link_finger_tip_2.dae"/>
      </geometry>
      <material name="carbon_fiber">
        <color rgba="0.792156862745098 0.819607843137255 0.933333333333333 1"/>
      </material>
    </visual>
    <collision>
      <geometry>
        <mesh filename="package://kinova_description/meshes/jaco2_link_finger_tip_2.dae"/>
      </geometry>
    </collision>
  </link>
  <joint name="jaco2_joint_finger_tip_2" type="revolute">
    <parent link="jaco2_link_finger_2"/>
    <child link="jaco2_link_finger_tip_2"/>
    <axis xyz="0 0 1"/>
    <origin rpy="0 0 0" xyz="0.035 -0.02595 -0.0025"/>
    <limit effort="30" lower="0" upper="0.698131700798" velocity="5"/>
    <mimic joint="jaco2_joint_finger_2" multiplier="0.0" offset="0.0"/>
  </joint>
  <link name="jaco2_link_finger_3">
    <visual>
      <geometry>
        <mesh filename="package://kinova_description/meshes/jaco2_link_finger_3.dae"/>
      </geometry>
      <material name="carbon_fiber">
        <color rgba="0.792156862745098 0.819607843137255 0.933333333333333 1"/>
      </material>
    </visual>
    <collision>
      <geometry>
        <mesh filename="package://kinova_description/meshes/jaco2_link_finger_3.dae"/>
      </geometry>
    </collision>
  </link>
  <joint name="jaco2_joint_finger_3" type="revolute">
    <parent link="jaco2_link_hand"/>
    <child link="jaco2_link_finger_3"/>
    <axis xyz="0 0 1"/>
    <origin rpy="-1.5161 1.1459 0.23978" xyz="0.03569 0.0216 -0.10071"/>
    <limit effort="30" lower="0" upper="0.698131700798" velocity="5"/>
  </joint>
  <link name="jaco2_link_finger_tip_3">
    <visual>
      <geometry>
        <mesh filename="package://kinova_description/meshes/jaco2_link_finger_tip_3.dae"/>
      </geometry>
      <material name="carbon_fiber">
        <color rgba="0.792156862745098 0.819607843137255 0.933333333333333 1"/>
      </material>
    </visual>
    <collision>
      <geometry>
        <mesh filename="package://kinova_description/meshes/jaco2_link_finger_tip_3.dae"/>
      </geometry>
    </collision>
  </link>
  <joint name="jaco3_joint_finger_tip_3" type="revolute">
    <parent link="jaco2_link_finger_3"/>
    <child link="jaco2_link_finger_tip_3"/>
    <axis xyz="0 0 1"/>
    <origin rpy="0 0 0" xyz="0.035 -0.02595 -0.0025"/>
    <limit effort="30" lower="0" upper="0.698131700798" velocity="5"/>
    <mimic joint="jaco2_joint_finger_3" multiplier="0.0" offset="0.0"/>
  </joint>
</robot>

